<?xml version="1.0"?>
<robot xmlns:xacro="http://www.ros.org/wiki/xacro">

  <xacro:macro name="diffbot" params="prefix">

  
  <link name="${prefix}base_footprint"/>

  <link
    name="${prefix}base_link">
    <inertial>
      <origin
        xyz="-0.025609 0.0093176 0.034957"
        rpy="0 0 0" />
      <mass
        value="2" />
      <inertia
        ixx="0.0016616"
        ixy="-5.2805E-05"
        ixz="-3.0797E-06"
        iyy="0.0024755"
        iyz="-1.1469E-06"
        izz="0.0030448" />
    </inertial>
    <visual>
      <origin
        xyz="0 0 0"
        rpy="0 0 0" />
      <geometry>
        <mesh
          filename="package://diffdrive_jetbot/description/meshes/base_link.STL" />
      </geometry>
      <material
        name="">
        <color
          rgba="0.61176 0.65882 0.67059 1" />
      </material>
    </visual>
    <collision>
      <origin
        xyz="0 0 0"
        rpy="0 0 0" />
      <geometry>
        <mesh
          filename="package://diffdrive_jetbot/description/meshes/base_link.STL" />
      </geometry>
    </collision>
  </link>
  <!-- Fixed joint between base_footprint and base_link -->
  <joint
    name="${prefix}body_fix_joint"
    type="fixed">
    <origin
      xyz="0 0 0.035"
      rpy="-1.5708 0 0" />
    <parent
      link="${prefix}base_footprint" />
    <child
      link="${prefix}base_link" />
    <axis
      xyz="0 0 0" />
  </joint>
  <link
    name="${prefix}caster_ball_link">
    <inertial>
      <origin
        xyz="-1.8666E-06 -8.4152E-07 -0.0059479"
        rpy="0 0 0" />
      <mass
        value="0.011917" />
      <inertia
        ixx="2.5586E-07"
        ixy="6.7546E-11"
        ixz="3.0679E-11"
        iyy="1.8138E-07"
        iyz="1.7478E-14"
        izz="2.6388E-07" />
    </inertial>
    <visual>
      <origin
        xyz="0 0 0"
        rpy="0 0 0" />
      <geometry>
        <mesh
          filename="package://diffdrive_jetbot/description/meshes/caster_ball_link.STL" />
      </geometry>
      <material
        name="">
        <color
          rgba="0.61176 0.65882 0.67059 1" />
      </material>
    </visual>
    <collision>
      <origin
        xyz="0 0 0"
        rpy="0 0 0" />
      <geometry>
        <mesh
          filename="package://diffdrive_jetbot/description/meshes/caster_ball_link.STL" />
      </geometry>
    </collision>
  </link>
  <joint
    name="${prefix}caster_ball_fix_joint"
    type="fixed">
    <origin
      xyz="-0.083 0.0208 0"
      rpy="-1.5708 0 3.1416" />
    <parent
      link="${prefix}base_link" />
    <child
      link="${prefix}caster_ball_link" />
    <axis
      xyz="0 0 0" />
  </joint>
  <link
    name="${prefix}camera_link">
    <inertial>
      <origin
        xyz="7.2979E-05 -0.0036847 -0.0021354"
        rpy="0 0 0" />
      <mass
        value="0.068956" />
      <inertia
        ixx="2.4451E-06"
        ixy="1.5517E-12"
        ixz="-1.8066E-08"
        iyy="3.8509E-06"
        iyz="1.5741E-11"
        izz="2.7785E-06" />
    </inertial>
    <visual>
      <origin
        xyz="0 0 0"
        rpy="0 0 0" />
      <geometry>
        <mesh
          filename="package://diffdrive_jetbot/description/meshes/camera_link.STL" />
      </geometry>
      <material
        name="">
        <color
          rgba="0.61176 0.65882 0.67059 1" />
      </material>
    </visual>
    <collision>
      <origin
        xyz="0 0 0"
        rpy="0 0 0" />
      <geometry>
        <mesh
          filename="package://diffdrive_jetbot/description/meshes/camera_link.STL" />
      </geometry>
    </collision>
  </link>
  <joint
    name="${prefix}camera_fix_joint"
    type="fixed">
    <origin
      xyz="0.053557 -0.057568 0"
      rpy="1.9199 -1.5708 3.1416" />
    <parent
      link="${prefix}base_link" />
    <child
      link="${prefix}camera_link" />
    <axis
      xyz="0 0 0" />
  </joint>
  <link
    name="${prefix}lidar_link">
    <inertial>
      <origin
        xyz="-0.0065398705841951 0.000690713934940602 0.0309531855778308"
        rpy="0 0 0" />
      <mass
        value="0.564294014597891" />
      <inertia
        ixx="0.000142259766419758"
        ixy="-2.48879198210457E-06"
        ixz="2.55066150802879E-06"
        iyy="0.000186813526823412"
        iyz="8.53957008589798E-08"
        izz="0.000308569075147343" />
    </inertial>
    <visual>
      <!-- Shift mesh down by 0.045 along z to compensate for frame shift up -->
      <origin
        xyz="0 0 -0.045 "
        rpy="0 0 0" />
      <geometry>
        <mesh
          filename="package://diffdrive_jetbot/description/meshes/lidar_link.STL" />
      </geometry>
      <material
        name="">
        <color
          rgba="0.611764705882353 0.658823529411765 0.670588235294118 1" />
      </material>
    </visual>
    <collision>
      <!-- Shift mesh down by 0.045 along z to compensate for frame shift up -->
      <origin
        xyz="0 0 -0.045"
        rpy="0 0 0" />
      <geometry>
        <mesh
          filename="package://diffdrive_jetbot/description/meshes/lidar_link.STL" />
      </geometry>
    </collision>
  </link>
  <joint
    name="${prefix}lidar_fix_joint"
    type="fixed">
    <!-- Raise lidar_link frame by 0.045 along z -->
     <!-- xyz="-0.011026 -0.10618-0.045 0 " -->
    <origin
      xyz="-0.011026 -0.1512 0 "
      rpy="1.5708 0 0" />
    <parent
      link="${prefix}base_link" />
    <child
      link="${prefix}lidar_link" />
    <axis
      xyz="0 0 0" />
  </joint>
  <link
    name="${prefix}left_wheel_link">
    <inertial>
      <origin
        xyz="-3.04495944265183E-05 0.0183179040454366 -1.07396547774597E-07"
        rpy="0 0 0" />
      <mass
        value="0.388137366198046" />
      <inertia
        ixx="0.000163568162825962"
        ixy="-1.71522947947033E-07"
        ixz="-2.55253489205791E-08"
        iyy="0.000281670214792073"
        iyz="-1.06397401901507E-09"
        izz="0.000163656330155147" />
    </inertial>
    <visual>
      <origin
        xyz="0 0 0"
        rpy="0 0 0" />
      <geometry>
        <mesh
          filename="package://diffdrive_jetbot/description/meshes/left_wheel_link.STL" />
      </geometry>
      <material
        name="">
        <color
          rgba="0.52156862745098 0.627450980392157 0.686274509803922 1" />
      </material>
    </visual>
    <collision>
      <origin
        xyz="0 0 0"
        rpy="0 0 0" />
      <geometry>
        <mesh
          filename="package://diffdrive_jetbot/description/meshes/left_wheel_link.STL" />
      </geometry>
    </collision>
  </link>
  <joint
    name="${prefix}left_wheel_continuous_joint"
    type="continuous">
    <origin
      xyz="0 0 0.0575"
      rpy="1.5708 0 0" />
    <parent
      link="${prefix}base_link" />
    <child
      link="${prefix}left_wheel_link" />
    <axis
      xyz="0 1 0" />
  </joint>
  <link
    name="${prefix}right_wheel_link">
    <inertial>
      <origin
        xyz="-3.04495944265183E-05 0.0183179040454366 -1.07396547774597E-07"
        rpy="0 0 0" />
      <mass
        value="0.388137366198046" />
      <inertia
        ixx="0.000163568162825962"
        ixy="-1.71522947947033E-07"
        ixz="-2.55253489205791E-08"
        iyy="0.000281670214792073"
        iyz="-1.06397401901507E-09"
        izz="0.000163656330155147" />
    </inertial>
    <visual>
      <origin
        xyz="0 0 0"
        rpy="0 0 3.14359" />
      <geometry>
        <mesh
          filename="package://diffdrive_jetbot/description/meshes/right_wheel_link.STL" />
      </geometry>
      <material
        name="">
        <color
          rgba="1 1 1 1" />
      </material>
    </visual>
    <collision>
      <origin
        xyz="0 0 0"
        rpy="0 0 3.14359" />
      <geometry>
        <mesh
          filename="package://diffdrive_jetbot/description/meshes/right_wheel_link.STL" />
      </geometry>
    </collision>
  </link>
  <joint
    name="${prefix}right_wheel_continuous_joint"
    type="continuous">
    <origin
      xyz="0 0 -0.0575"
      rpy="-1.5708 3.14359 3.14359" />
    <parent
      link="${prefix}base_link" />
    <child
      link="${prefix}right_wheel_link" />
    <axis
      xyz="0 1 0" />
  </joint>

  </xacro:macro>

</robot>
